<robot name="biped">
    <link name="base">
	    <visual>
	      <geometry>
	        <box size="0.30 0.30 0.30"/>
	      </geometry>
	      <material name="gray">
	        <color rgba="0.3 0.3 0.3 1.0"/>
	      </material>
	    </visual>        
    </link>
    
    <!-- LEFT LEG -->
    <link name="L_hipassembly">
	    <visual>
	      <origin rpy="0.0 0.0 0.0" xyz="0.0 0.0 0.0"/>
	      <geometry>
	        <mesh filename="package://xpp_hyq/meshes/leg/hipassembly.dae" scale="1 1 1"/>
	      </geometry>
	      <material name="white"/>
	    </visual>        
    </link>
    <link name="L_upperleg">
	    <visual>
	      <origin rpy="0.0 0.0 0.0" xyz="0.0 0.0 0.0"/>
	      <geometry>
	        <mesh filename="package://xpp_hyq/meshes/leg/upperleg.dae" scale="1 1 1"/>
	      </geometry>
	      <material name="blue"/>
	    </visual>
    </link>
    <link name="L_lowerleg">
	    <visual>
	      <geometry>
	        <mesh filename="package://xpp_hyq/meshes/leg/lowerleg.dae" scale="1 1 1"/>
	      </geometry>
	      <material name="blue"/>
	    </visual>        
    </link>
    
    <joint name="L_haa_joint" type="revolute">
        <origin xyz="0.00000 0.1 -0.15000" rpy="2.0344439357957036 1.5707962290814481 -1.1071487177940917"/>
        <parent link="base"/>
        <child  link="L_hipassembly"/>
        <limit effort="200" lower="-1.6" upper="1.6" velocity="1.0"/>
        <axis xyz="0 0 1"/>
    </joint>
    <joint name="L_hfe_joint" type="revolute">
        <origin xyz="0.08000 0.00000 0.00000" rpy="1.5707963705062866 -0.0 0.0"/>
        <parent link="L_hipassembly"/>
        <child  link="L_upperleg"/>
        <limit effort="200" lower="-1.6" upper="1.6" velocity="1.0"/>
        <axis xyz="0 0 1"/>
    </joint>
    <joint name="L_kfe_joint" type="revolute">
        <origin xyz="0.35000 0.00000 0.00000" rpy="0.0 0.0 0.0"/>
        <parent link="L_upperleg"/>
        <child  link="L_lowerleg"/>
        <limit effort="200" lower="-1.6" upper="1.6" velocity="1.0"/>
        <axis xyz="0 0 1"/>
    </joint>
    
    
    
    <!-- RIGHT LEG -->
    <link name="R_hipassembly">
      <visual>
        <origin rpy="0.0 0.0 0.0" xyz="0.0 0.0 0.0"/>
        <geometry>
          <mesh filename="package://xpp_hyq/meshes/leg/hipassembly.dae" scale="1 1 1"/>
        </geometry>
        <material name="white"/>
      </visual>        
    </link>
    <link name="R_upperleg">
      <visual>
        <origin rpy="0.0 0.0 0.0" xyz="0.0 0.0 0.0"/>
        <geometry>
          <mesh filename="package://xpp_hyq/meshes/leg/upperleg.dae" scale="1 1 1"/>
        </geometry>
        <material name="blue"/>
      </visual>
    </link>
    <link name="R_lowerleg">
      <visual>
        <geometry>
          <mesh filename="package://xpp_hyq/meshes/leg/lowerleg.dae" scale="1 1 1"/>
        </geometry>
        <material name="blue"/>
      </visual>        
    </link>
    
    <joint name="R_haa_joint" type="revolute">
        <origin xyz="0.00000 -0.1 -0.15000" rpy="2.0344439357957036 1.5707962290814481 -1.1071487177940917"/>
        <parent link="base"/>
        <child  link="R_hipassembly"/>
        <limit effort="200" lower="-1.6" upper="1.6" velocity="1.0"/>
        <axis xyz="0 0 1"/>
    </joint>
    <joint name="R_hfe_joint" type="revolute">
        <origin xyz="0.08000 0.00000 0.00000" rpy="1.5707963705062866 -0.0 0.0"/>
        <parent link="R_hipassembly"/>
        <child  link="R_upperleg"/>
        <limit effort="200" lower="-1.6" upper="1.6" velocity="1.0"/>
        <axis xyz="0 0 1"/>
    </joint>
    <joint name="R_kfe_joint" type="revolute">
        <origin xyz="0.35000 0.00000 0.00000" rpy="0.0 0.0 0.0"/>
        <parent link="R_upperleg"/>
        <child  link="R_lowerleg"/>
        <limit effort="200" lower="-1.6" upper="1.6" velocity="1.0"/>
        <axis xyz="0 0 1"/>
    </joint>
    
    
</robot>

